output/18:00.txt
VWAP at time: 18:00
Symbol  VWAP
--------------
TTTN   25.5000
PPLC   35.5900
MSBF   18.0000
TAPR   24.2400
LEJU   1.5700
CKX   10.2700
SENEB   28.3600
KFFB   7.3660
USLM   69.8104
WRLSW   0.2513
PRB   24.4380
NTIP   2.6200
GLADN   25.2500
PWZ   25.7200
MFAC+   0.3400
DYNC   96.4983
ZB-H   25.2750
VFMO   73.7200
WSTG   10.6400
HDMV   32.6400
CRUSC   100.0200
FIDI   20.8200
PEB-F   24.1200
SB-D   19.5900
FFSG   24.8200
GFED   21.8055
FPEI   18.6600
AGFSW   0.1002
WHFBZ   25.5000
GSAH   9.8800
KTH   30.5600
MXE   11.1300
OSBCP   10.5000
SOL   1.7347
SUB   105.5980
JPHY   49.5200
FLTW   23.5000
KOMP   29.5100
AXJV   35.1300
LSAF   22.9800
MICR   2.5150
NUMG   28.6000
FTV-A   977.5300
DWLV   29.5800
VAMO   22.2468
LMHA   26.3900
SPAQ   9.7600
PEI-B   19.5000
PXJ   6.9443
STPP   29.5000
TDA   22.1400
LTS-A   23.9545
DMRI   47.0300
NTP   8.6001
JKG   179.0829
NTC   11.6300
CMSA   25.0154
FINZ   8.0108
ALP-Q   25.0152
BDCS   19.1979
CSSEP   24.7567
ISRA   30.8000
LXP-C   49.5879
ODC   26.2602
KTN   30.0000
BRAC   10.1500
FLKR   22.6300
TY-   52.2500
DGSE   0.4891
IEME   25.0900
PSMG   13.6400
CLNY-E   25.3419
GSSC   42.5531
BRG-C   25.0800
AFC   25.3900
CMRE-E   23.2058
LYL   1.3900
CPE-A   51.5056
MMDMW   0.2705
IDHD   26.9500
NMT   12.4650
AGT   23.8000
ULVM   49.0000
NS-A   23.2000
OUSM   25.6000
OFED   26.8863
SIF   3.1550
FIV   8.9247
AADR   43.5600
RGI   114.5900
SYG   78.0500
PAGG   25.6344
FLEE   22.3500
MZA   12.8600
TWO-E   23.8900
KURE   18.3077
CDOR   8.2154
CSA   44.3000
LDRI   24.6700
CLNY-B   25.0427
UBG   33.2884
TAXF   50.1000
DHF   2.9459
AGGP   18.9653
FIBR   97.2650
CMFNL   25.1900
ARKR   18.6093
CN   31.3396
GDVD   25.7000
ARNC-   87.1615
NEON   2.5003
WPG-I   15.2700
ESGL   30.0600
PBB   24.9103
FEUZ   37.4701
MDLX   21.6000
MCI   15.1401
FLJP   24.0175
DMRS   52.1900
ENTR   15.6500
GYLD   16.5470
CNXT   22.1000
KIM-K   23.3900
ABR-B   25.6800
KIQ   0.6097
OEUR   22.9467
HDG   44.3967
LDRS   21.3615
IBND   33.3927
PUK-   26.0400
FCA   25.6400
GJS   20.1000
GRI   45.3400
HUSE   34.5300
CVY   21.4615
GAB-D   25.6500
FLM   49.0120
PEK   34.2200
MS-E   28.0837
ERM   19.9200
RFV   65.5400
INN-D   23.7500
SSW-D   23.2800
ARI-C   25.2112
NCZ-A   23.8800
HGSD   24.3400
CMCT   17.6497
SKOR   49.7100
HECO   39.8900
LEAD   32.0635
TLEH   28.2800
AGMH   27.0307
TWN   16.0460
JJN   49.4300
DBLV   63.0900
RGT   9.5433
ICAN   27.4100
WFC-L   1293.5135
PRNT   21.8900
LQDH   93.1000
NDRAW   0.7800
DJCI   14.9500
SSNT   2.2744
RJA   5.7500
PPLN   17.1200
RILYZ   24.4721
TOO-E   18.6148
PRE-I   24.9410
MBG   25.5277
FLTB   49.4710
TBLU   27.3900
MOTI   30.7563
DVHL   17.5123
EURL   24.0851
STN   23.6000
MNE   12.7273
JHME   25.7500
DDBI   26.8400
GIGB   48.2400
GRNB   25.7100
TYBS   20.4583
JHI   15.3800
APT   4.0988
CFFAU   10.0890
IDOG   25.8917
RWUI   51.1400
RWED   52.2200
DGT   80.7400
SSPY   43.1900
FEUL   76.6900
HYGH   88.5300
UBR   84.6306
SEB   3836.3600
CRD.B   9.4600
DQML   24.1300
KNOW   37.4239
DIVB   25.3600
FEU   31.1442
ESP   26.4000
EUDG   23.6750
JUST   38.4510
IFRA   24.9400
FXA   72.4286
FQAL   31.8825
HMLP-A   25.1270
TMCX   10.0923
JKF   101.3488
SPDN   29.8290
CIO-A   22.0000
LRGE   30.6900
PNBK   14.6000
JHY   10.0211
IZRL   20.8225
PSB-X   22.4276
IGEB   48.1808
TDTF   24.2484
CHGX   18.9800
DDLS   29.1100
ACES   25.0600
IHY   23.9700
USMF   27.8806
FILL   19.7712
MCN   6.6915
CNYA   24.5500
VMM   12.1683
RHE-A   3.7500
FIHD   153.8500
GMF   93.0715
EMDV   56.4700
HYGV   47.7094
TUZ   50.1872
IPAC   54.3333
CZA   64.2798
LOAC   9.9495
MFO   25.5800
CNACR   0.1410
FDNI   20.2850
VIOG   150.1261
IQDG   26.9800
FLIN   21.1600
WIL   64.4500
AUSF   23.8000
DGZ   13.9650
WILC   8.1400
DFP   22.4981
AAAU   13.1000
AEF   7.0319
IVR-A   24.9635
CEL   5.0795
FEO   13.5733
DJPY   23.0300
UMH-B   26.0400
EELV   24.2201
TCTL   29.0300
MFCB   6.7600
MIND   3.9543
MCX   24.8800
AUG   1.0349
PY   30.3080
JPXN   57.9525
LGI   14.5448
FVAL   32.2241
NYMTP   23.0401
GS-A   19.1686
SVT   11.4600
MVCD   25.2550
BML-H   19.3528
MUJ   12.9433
SUSC   24.3000
NXN   13.0925
RIVE   12.6000
DL   7.1100
NUBD   24.3700
LGLV   93.4539
RFDA   30.3763
PXMV   30.1638
DVP   31.9502
PBTP   24.5367
CODI-B   20.3142
SSWN   25.1500
XYF   5.3651
GDV-A   25.7200
GLOG-A   25.7898
YLDE   27.4900
DVOL   19.1026
FGB   6.1000
DD-B   99.9623
NEE-K   24.3630
BKTI   4.0700
KIM-M   21.9800
CBND   31.1894
HCCHR   0.2900
DTEC   26.6047
TMK-C   26.2157
MDLQ   22.3906
SPRT   2.4999
PYS   15.5989
ENJ   24.0024
VNRX   2.5559
PSR   83.8300
STNLU   10.1600
KBA   26.7495
GSIE   27.1668
NHA   9.6599
MYC   13.1799
AFTY   14.5200
TPGH+   1.2500
IHC   35.8092
VBF   17.6101
WBIG   23.3400
MMD   19.6604
USWSW   0.6700
PGP   13.6435
ZB-G   27.0441
BFS-D   22.4200
YMLI   12.3300
EMP   23.8064
JHMU   28.8006
FDTS   36.1800
JHS   13.4084
SDR   1.0194
QEMM   58.1900
BSCR   19.1576
JJS   41.7900
DAUD   28.4500
JHMT   42.7340
TSQ   6.1953
NRP   38.1644
UYM   54.5200
FDM   44.6067
LDP   23.2495
PBJ   31.1300
SBB   33.8123
TCI   32.9050
WYY   0.4335
BSJN   25.5495
AHT-F   21.1700
VEGI   28.2089
DTJ   24.7300
MVC   8.8121
ULST   40.2950
NYF   54.9333
PLYM   15.5572
HUSV   23.3700
WIA   10.9221
UMDD   91.7772
AMH-G   22.4885
EGIF   14.1060
HYMB   55.7330
EMIF   29.7574
WEAT   6.0270
NAII   11.0699
ANH-C   24.6800
POPE   70.0762
KKR-A   26.7900
ECCA   25.4900
AMS   2.5313
FCOR   48.3998
QTS-A   25.4672
ADRD   20.6183
STT-D   26.4921
GLOP-A   23.1398
GAL   36.4967
WHLRP   10.2946
FLTR   25.0075
SSW-I   23.7233
BSJM   24.1596
BMLP   46.8307
RZG   113.3250
OMFL   26.4462
PMM   7.0942
DNI   10.8774
ROAM   23.9500
MNR-C   23.3121
IBDT   25.3800
STI-A   22.0206
GQRE   61.4351
FXB   127.0937
PTVCA   17.9423
DLR-J   22.9740
MSD   8.8525
DALI   18.5500
FONE   45.6226
BML-L   21.2848
FLC   18.4028
IYY   133.5535
CODI-A   19.4838
FOF   12.0965
BAC-A   25.8035
EMX   1.1400
EWX   43.6075
AMRB   13.7609
FCAL   49.9700
ELU   22.9892
HAO   24.0261
EOD   5.1316
BSCJ   20.5353
GDXS   13.2920
FRC-D   24.1381
ROSEW   0.4275
USVM   49.6000
FLMNW   0.7995
PNF   12.5850
AKP   13.7201
WFE-A   25.7483
NES   13.5451
IPB   25.7500
SPE   12.7517
TCO-J   24.7967
ADRA   30.4129
SMLV   89.4413
GXG   8.8773
CRHM   3.1831
ACU   16.8700
CIM-A   25.2748
KF   31.4359
GLDM   13.1659
RETO   1.8114
PSB-U   23.8263
GIG+   0.2160
LSBK   15.4254
PSB-V   24.7305
SPFF   11.5282
RCD   98.1100
TVC   25.4019
DCP-B   23.8737
GS-B   26.3501
GDV-G   24.6233
PIY   10.3600
BSJL   24.3618
PICB   25.8067
WIW   10.5016
STND   31.9823
USEQ   26.1400
CIZN   21.6062
TANNI   25.4882
JHX   10.9344
LVUS   26.9700
IRET-C   23.8305
THST   2.1315
CSPI   9.8079
LDUR   98.9800
BLES   26.6000
PCEF   21.5303
PNC-Q   24.8622
LTL   34.8900
TAWK   24.2965
RWGV   50.7700
RWLS   51.1800
PFIN   7.8173
CEY   24.5788
MMTM   114.8214
PWS   23.9960
AVH   4.5208
RF-B   26.4983
FRAK   12.5000
IMTB   48.4900
PCG-C   16.8241
NC   33.9655
LTPZ   62.5100
EHT   9.5100
FTAG   23.7054
GTO   50.7088
SSW-H   23.2709
HJLIW   0.4000
MET-A   23.0460
MAGA   25.5739
PIHPP   22.1118
NNVC   0.3052
SIJ   16.2703
IQDY   23.6200
DOD   23.9545
SSG   17.2990
SHYD   24.3467
DEF   46.8780
PZN   8.4665
GGZ   11.1850
PPX   25.1528
DSS   0.9901
IAF   5.2259
USHY   47.7020
CMSC   25.4976
ZF   9.1929
GHII   25.6377
NEWTI   25.5929
TVE   24.8238
DNN   0.5178
HEWP   20.9500
NOM   12.3313
GS-D   19.0676
GIG^   0.2400
MHH   7.9900
DLNG-A   20.8500
SNV-D   25.1153
ABR-C   25.6339
ONEO   67.8200
NUAG   23.3678
TRT   2.9563
CLTL   105.4600
JPME   62.0600
WFHY   49.4000
EWO   19.9200
PDT   15.5881
CNP-B   52.8365
MITT-B   25.3427
VJET   2.0875
NTIC   30.9395
PCQ   16.9414
INF   11.6343
TCBIL   25.3482
ALD   44.0657
SHAG   49.1200
DTF   12.9500
GLADD   25.1030
AFGH   26.0917
SRC-A   22.1834
PPT   4.9617
EYESW   0.3300
NORW   12.2837
SDD   14.7600
LINDW   2.6535
CCM   3.0901
SGZA   24.9533
SRG-A   23.2330
YXI   19.3103
DEMG   24.7850
INTF   25.9394
GVAL   22.9384
ELJ   25.3300
LOR   9.3833
DCF   8.4035
TNP-E   21.5612
MOG.B   88.1051
NOVN   1.3427
BYM   12.9831
DBGR   24.7300
PT   10.9988
WHLRD   11.8384
ISCF   27.9973
